<mujoco model="right_faive">

    <body name="root">
        <!-- so that the base can be colored separately in IsaacGym, make it into its own body -->
        <geom mesh="base" rgba="0.2 0.2 0.2 1"/>
        <body name="palm">
            <!-- So that the contact convex hull can be calculated for each distinct component rather than for the entire palm structure, separate it into separate geoms -->
            <geom mesh="palm"/>
            <geom mesh="index_meta"/>
            <geom mesh="middle_meta"/>
            <geom mesh="ring_meta"/>
            <geom mesh="pinky_meta"/>
            
            <body name="thumb_base" pos="-0.029450 0.061590 -0.006270" quat="0.805372 0.000000 0.402853 -0.434839">
                <joint name="root2thumb_base" axis="1.000000 0.000000 0.000000" pos="0.000000 0.000000 0.000000" range="0 2.27" />
                <geom mesh="thumb_base" pos="0.047824 -0.019868 0.044923" quat="-0.805372 0.000000 0.402853 -0.434839" />
                <body name="thumb_pp" pos="0.000000 -0.010014 -0.011168" quat="0.701176 -0.091392 -0.400078 -0.583042">
                    <joint name="thumb_base2pp" axis="1.000000 -0.000000 -0.000000" pos="0.000000 0.000000 0.000000" range="-1.66 1.05" />
                    <geom mesh="thumb_pp" pos="0.044783 0.058589 0.009603" quat="0.472351 0.482454 -0.000000 0.737647" />
                    <body name="thumb_mp_virt" pos="0.006036 -0.014416 -0.034587" quat="0.419319 -0.052705 0.308003 0.852366">
                        <joint name="thumb_pp2mp_virt" axis="1.000000 0.000000 0.000000" pos="0.000000 0.000000 0.000000" range="0 0.96" />
                        <inertial pos="0.009525 -0.041187 0.083647" mass="0.001" diaginertia="4E-10 4E-10 3E-10" quat="-0.801383 0.000000 0.595590 -0.055291" />
                        <body name="thumb_mp" pos="0.000038 -0.002927 -0.011638" quat="-1.000000 0.000000 -0.000000 -0.000000">
                            <joint name="thumb_pp2mp" axis="1.000000 0.000000 0.000000" pos="0.000000 0.000000 0.000000" range="0 0.96" />
                            <geom mesh="thumb_mp" pos="0.009487 -0.038260 0.095285" quat="-0.801383 0.000000 0.595590 -0.055291" />
                            <body name="thumb_dp_virt" pos="0.000084 -0.006463 -0.025699" quat="-1.000000 0.000000 -0.000000 -0.000000">
                                <joint name="thumb_mp2dp_virt" axis="1.000000 0.000000 0.000000" pos="0.000000 0.000000 0.000000" range="0 0.68" />
                                <inertial pos="0.009403 -0.031797 0.120984" mass="0.001" diaginertia="4E-10 4E-10 3E-10" quat="-0.801383 0.000000 0.595590 -0.055291" />
                                <body name="thumb_dp" pos="0.000027 -0.002196 -0.008728" quat="-1.000000 0.000000 -0.000000 -0.000000">
                                    <joint name="thumb_mp2dp" axis="1.000000 0.000000 0.000000" pos="0.000000 0.000000 0.000000" range="0 0.68" />
                                    <geom mesh="thumb_dp" pos="0.009375 -0.029601 0.129712" quat="-0.801383 0.000000 0.595590 -0.055291" />
                                    <body name="thumb_fingertip" pos="0.000386 -0.000394 -0.012633" euler="4.7 -0.25 2.92">
                                    </body>
                                </body>
                            </body>
                        </body>
                    </body>
                </body>
            </body>
            <body name="index_pp_virt">
                <joint name="root2index_pp_virt" axis="-0.990425994580321  -0.104241812967506  -0.090498583905110" pos="-0.029320000000000   0.115440000000000   0.017930000000000" range="0 0.83"/>
                <inertial pos="0 0 0" mass="0.001" diaginertia="4E-10 4E-10 3E-10" />
                <body name="index_pp">
                    <joint name="root2index_pp" axis="-0.990425994580321  -0.104241812967506  -0.090498583905110" pos="-0.031385146447244   0.133190847457549   0.020084665795489" range="0 0.83"/>
                    <geom mesh="index_pp"/>
                    <body name="index_mp_virt">
                        <joint name="index_pp2mp_virt" axis="-0.990425994580321  -0.104241812967506  -0.090498583905110" pos="-0.034941787550830   0.163761751412218   0.023795479109943" range="0 0.96"/>
                        <inertial pos="0 0 0" mass="0.001" diaginertia="4E-10 4E-10 3E-10" />
                        <body name="index_mp">
                            <joint name="index_pp2mp" axis="-0.990425994580321  -0.104241812967506  -0.090498583905110" pos="-0.036318551848992   0.175595649717251   0.025231922973603" range="0 0.96"/>
                            <geom mesh="index_mp"/>
                            <body name="index_dp_virt">
                                <joint name="index_mp2dp_virt" axis="-0.990425994580321  -0.104241812967506  -0.090498583905110" pos="-0.039014715266226   0.198770367231273   0.028044958873269" range="0 0.68"/>
                                <inertial pos="0 0 0" mass="0.001" diaginertia="4E-10 4E-10 3E-10" />
                                <body name="index_dp">
                                    <joint name="index_mp2dp" axis="-0.990425994580321  -0.104241812967506  -0.090498583905110" pos="-0.040047288489848   0.207645790960048   0.029122291771014" range="0 0.68"/>
                                    <geom mesh="index_dp"/>
                                    <body name="index_fingertip" pos="-0.0402	0.2175	0.0261" euler="-2.9 0.11 -1.66">
                                    </body>
                                </body>
                            </body>
                        </body>
                    </body>
                </body>
            </body>

            <body name="middle_pp_virt">
                <joint name="root2middle_pp_virt" axis="-1     0     0" pos="-0.005500000000000   0.117620000000000   0.019690000000000" range="0 0.83"/>
                <inertial pos="0 0 0" mass="0.001" diaginertia="4E-10 4E-10 3E-10" />
                <body name="middle_pp">
                    <joint name="root2middle_pp" axis="-1     0     0" pos="-0.005500000000000   0.135485830729544   0.021883648181293" range="0 0.83"/>
                    <geom mesh="middle_pp"/>
                    <body name="middle_mp_virt">
                        <joint name="middle_pp2mp_virt" axis="-1     0     0" pos="-0.005500000000000   0.170224946036990   0.026149075200473" range="0 0.96"/>
                        <inertial pos="0 0 0" mass="0.001" diaginertia="4E-10 4E-10 3E-10" />
                        <body name="middle_mp">
                            <joint name="middle_pp2mp" axis="-1     0     0" pos="-0.005500000000000   0.182135499856686   0.027611507321335" range="0 0.96"/>
                            <geom mesh="middle_mp"/>
                            <body name="middle_dp_virt">
                                <joint name="middle_mp2dp_virt" axis="-1     0     0" pos="-0.005500000000000   0.207445426723540   0.030719175578166" range="0 0.68"/>
                                <inertial pos="0 0 0" mass="0.001" diaginertia="4E-10 4E-10 3E-10" />
                                <body name="middle_dp">
                                    <joint name="middle_mp2dp" axis="-1     0     0" pos="-0.005500000000000   0.216378342088312   0.031815999668812" range="0 0.68"/>
                                    <geom mesh="middle_dp"/>
                                    <body name="middle_fingertip" pos="-0.0055	0.2251	0.0272" euler="-2.92 0.0 -1.565">
                                    </body>
                                </body>
                            </body>
                        </body>
                    </body>index
                </body>
            </body>

            <body name="ring_pp_virt">
                <joint name="root2ring_pp_virt" axis="-0.990425994580321   0.104241812967506   0.090498583905110" pos="0.018090000000000   0.112480000000000   0.018220000000000" range="0 0.83"/>
                <inertial pos="0 0 0" mass="0.001" diaginertia="4E-10 4E-10 3E-10" />
                <body name="ring_pp">
                    <joint name="root2ring_pp" axis="-0.990425994580321   0.104241812967506   0.090498583905110" pos="0.020155146447243   0.130230847457549   0.020374665795489" range="0 0.83"/>
                    <geom mesh="ring_pp"/>
                    <body name="ring_mp_virt">
                        <joint name="ring_pp2mp_virt" axis="-0.990425994580321   0.104241812967506   0.090498583905110" pos="0.023711787550830   0.160801751412218   0.024085479109943" range="0 0.96"/>
                        <inertial pos="0 0 0" mass="0.001" diaginertia="4E-10 4E-10 3E-10" />
                        <body name="ring_mp">
                            <joint name="ring_pp2mp" axis="-0.990425994580321   0.104241812967506   0.090498583905110" pos="0.025088551848992   0.172635649717251   0.025521922973603" range="0 0.96"/>
                            <geom mesh="ring_mp"/>
                            <body name="ring_dp_virt">
                                <joint name="ring_mp2dp_virt" axis="-0.990425994580321   0.104241812967506   0.090498583905110" pos="0.027784715266226   0.195810367231273   0.028334958873269" range="0 0.68"/>
                                <inertial pos="0 0 0" mass="0.001" diaginertia="4E-10 4E-10 3E-10" />
                                <body name="ring_dp">
                                    <joint name="ring_mp2dp" axis="-0.990425994580321   0.104241812967506   0.090498583905110" pos="0.028817288489848   0.204685790960048   0.029412291771014" range="0 0.68"/>
                                    <geom mesh="ring_dp"/>
                                    <body name="ring_fingertip" pos="0.02695	0.216	0.0244" euler="-2.92 -0.125 -1.425">
                                    </body>
                                </body>
                            </body>
                        </body>
                    </body>
                </body>
            </body>

            <body name="pinky_pp_virt">
                <joint name="root2pinky_pp_virt" axis="-0.950980299137689   0.223061123902897   0.214196651829969" pos="0.041170000000000   0.101870000000000   0.013200000000000" range="0 0.83"/>
                <inertial pos="0 0 0" mass="0.001" diaginertia="4E-10 4E-10 3E-10" />
                <body name="pinky_pp">
                    <joint name="root2pinky_pp" axis="-0.950980299137689   0.223061123902897   0.214196651829969" pos="0.045651869374116   0.119205095457698   0.015045890675491" range="0 0.83"/>
                    <geom mesh="pinky_pp"/>
                    <body name="pinky_mp_virt">
                        <joint name="pinky_pp2mp_virt" axis="-0.950980299137689   0.223061123902897   0.214196651829969" pos="0.052374673435289   0.145207738644245   0.017814726688728" range="0 0.96"/>
                        <inertial pos="0 0 0" mass="0.001" diaginertia="4E-10 4E-10 3E-10" />
                        <body name="pinky_mp">
                            <joint name="pinky_pp2mp" axis="-0.950980299137689   0.223061123902897   0.214196651829969" pos="0.055362586351366   0.156764468949377   0.019045320472388" range="0 0.96"/>
                            <geom mesh="pinky_mp"/>
                            <body name="pinky_dp_virt">
                                <joint name="pinky_mp2dp_virt" axis="-0.950980299137689   0.223061123902897   0.214196651829969" pos="0.060217944839991   0.175544155695216   0.021045035370837" range="0 0.68"/>
                                <inertial pos="0 0 0" mass="0.001" diaginertia="4E-10 4E-10 3E-10" />
                                <body name="pinky_dp">
                                    <joint name="pinky_mp2dp" axis="-0.950980299137689   0.223061123902897   0.214196651829969" pos="0.062458879527049   0.184211703424065   0.021967980708582" range="0 0.68"/>
                                    <geom mesh="pinky_dp"/>
                                    <body name="pinky_fingertip" pos="0.06295	0.1938	0.0186" euler="-2.92 -0.25 -1.3">
                                    </body>
                                </body>
                            </body>
                        </body>
                    </body>
                </body>
            </body>
        </body>
    </body>
    
</mujoco>