<mujoco model="right_faive">

    <!-- match the initial pose of P0, with the palm facing downwards (-z) and the fingers point +y -->
    <body name="root" euler="-1.5707 0 3.1415" >
        <!-- so that the base can be colored separately in IsaacGym, make it into its own body -->
        <!-- <geom mesh="base" rgba="0.2 0.2 0.2 1"/> -->
        <body name="palm">
            <!-- So that the contact convex hull can be calculated for each distinct component rather than for the entire fixed base, separate it into separate geoms -->
            <geom mesh="palm_tower"/>
            <!--index components spawn at ring finger with ring finger orientation: quat (index_base_rot*ring_base_rot.inverse) brings it to index finger orientation, and pos to index position (position vector is hardcoded, but approx -MCPA1_ring + MCPA1_index)-->
            <!-- <geom mesh="index_lm" quat ="0.9909687390921409 -0.019419136351110703 0.11286425148204841 -0.06975325098449901" pos = "0.0470703511  -0.00210067481 0.00667793612"/> -->
            <!-- <geom mesh="middle_lm"/> -->
            <!-- <geom mesh="pinky_lm"/> -->
            <!-- <geom mesh="ring_lm"/> -->
            <!-- <site name="p01" pos="0.026435 0.018613 0.026355 " size="0.001" rgba="1 0.1 0.1 1"/> -->
            <!-- <site name="p02" pos="0.032864 0.032727 0.013103 " size="0.001" rgba="0.1 1 0.1 1"/> -->
            <body name="thumb_base" pos="0.0302924 0.0270814 0.0184038" quat="0.29739387 0.50396621 -0.79122378  0.1775947 ">
                <joint name="root2thumb_base" axis="1.000000 0.000000 0.000000" pos="0.000000 0.000000 0.000000" range="0 2.27" />
                <geom mesh="thumb_base" pos="0.047824 -0.019868 0.044923" quat="-0.805372 0.000000 0.402853 -0.434839" />
                <body name="thumb_pp" pos="0.000000 -0.010014 -0.011168" quat="0.701176 -0.091392 -0.400078 -0.583042">
                    <joint name="thumb_base2pp" axis="1.000000 -0.000000 -0.000000" pos="0.000000 0.000000 0.000000" range="-1.66 1.05" />
                    <geom mesh="thumb_pp" pos="0.044783 0.058589 0.009603" quat="0.472351 0.482454 -0.000000 0.737647" />
                    <body name="thumb_mp_virt" pos="0.006036 -0.014416 -0.034587" quat="0.419319 -0.052705 0.308003 0.852366">
                        <joint name="thumb_pp2mp_virt" axis="1.000000 0.000000 0.000000" pos="0.000000 0.000000 0.000000" range="0 0.96" />
                        <inertial pos="0.009525 -0.041187 0.083647" mass="0.001" diaginertia="4E-10 4E-10 3E-10" quat="-0.801383 0.000000 0.595590 -0.055291" />
                        <body name="thumb_mp" pos="0.000038 -0.002927 -0.011638" quat="-1.000000 0.000000 -0.000000 -0.000000">
                            <joint name="thumb_pp2mp" axis="1.000000 0.000000 0.000000" pos="0.000000 0.000000 0.000000" range="0 0.96" />
                            <geom mesh="thumb_mp" pos="0.009487 -0.038260 0.095285" quat="-0.801383 0.000000 0.595590 -0.055291" />
                            <body name="thumb_dp_virt" pos="0.000084 -0.006463 -0.025699" quat="-1.000000 0.000000 -0.000000 -0.000000">
                                <joint name="thumb_mp2dp_virt" axis="1.000000 0.000000 0.000000" pos="0.000000 0.000000 0.000000" range="0 0.68" />
                                <inertial pos="0.009403 -0.031797 0.120984" mass="0.001" diaginertia="4E-10 4E-10 3E-10" quat="-0.801383 0.000000 0.595590 -0.055291" />
                                <body name="thumb_dp" pos="0.000027 -0.002196 -0.008728" quat="-1.000000 0.000000 -0.000000 -0.000000">
                                    <joint name="thumb_mp2dp" axis="1.000000 0.000000 0.000000" pos="0.000000 0.000000 0.000000" range="0 0.68" />
                                    <geom mesh="thumb_dp" pos="0.009375 -0.029601 0.129712" quat="-0.801383 0.000000 0.595590 -0.055291" />
                                    <body name="thumb_fingertip" pos="0.000386 -0.000394 -0.012633" euler="4.7 -0.25 2.92">
                                    </body>
                                </body>
                            </body>
                        </body>
                    </body>
                </body>
            </body>

            <!--currently the meshes for index_um and index_pp are hardcoded thorugh mujoco (see yaml_conversion.py)-->
            <!-- <site name="p11" pos="0.029883 0.085608 -0.001404 " size="0.001" rgba="1 0.1 0.1 1"/> -->
            <!-- <site name="p12" pos="0.016650 0.087193 0.004395 " size="0.001" rgba="0.1 1 0.1 1"/> -->
            <!-- <site name="p13" pos="0.016950 0.086741 -0.002082 " size="0.001" rgba="0.1 0.1 0.1 1"/> -->
            <!-- <site name="p14" pos="0.017674 0.094691 -0.002603 " size="0.001" rgba="0.1 0.1 1 1"/> -->
            <body name="index_um_virt" quat ="0.5167689347304412 -0.506005226896599 0.5258539639535457 0.44764515751343686" pos = "0.0241405 0.0941245 -0.002264">
                <joint name="index_abd_virt" axis = "1 0 0" range="-0.264 0.264"/>
                <inertial pos="0 0 0" mass="0.001" diaginertia="4E-10 4E-10 3E-10" />
                <body name="index_um" pos="0 0 0.018">
                    <joint name="index_abd" axis = "1 0 0" range="-0.264 0.264"/>
                    <geom mesh="index_um" quat="0.6747394337578665 0.059955532672107535 0.039660080772529006 -0.7345468729953414" pos = "-0.00167  -0.02403002404 0.00664"/>
                    <body name="index_pp_virt" quat="0.7071067811865476 0.0 -1.0408340855860843e-17 -0.7071067811865475" pos="0 0 -0.00743303472">
                        <joint name="root2index_pp_virt" axis="1 0 0" pos = "0.         0.00270000102 0." range="-0.157 0.829"/>
                        <inertial pos="0 0 0" mass="0.001" diaginertia="4E-10 4E-10 3E-10" />
                        <body name="index_pp" pos="0 0 0.018">
                            <joint name="root2index_pp" axis="1 0 0" pos = "0.         0.00250000102 0." range="-0.157 0.829"/>
                            <geom mesh="index_pp" quat="0.9965159041385382 0.014351051665437375 0.07043887577876032 -0.042290245850220926" pos = "0.02403002404 -0.00167 -0.0040"/>
                            <body name="index_pp_sens" pos="0 -0.004 0.018">
                            </body>
                            <body name="index_mp_virt" pos="0.          0.         0.03101612481">
                                <joint name="index_pp2mp_virt" axis="1 0 0" pos = "0.         0.00370000102 0." range="-0.131 0.960"/>
                                <inertial pos="0 0 0" mass="0.001" diaginertia="4E-10 4E-10 3E-10" />
                                <body name="index_mp" pos=" 0.  0. 0.012">
                                    <joint name="index_pp2mp" axis="1 0 0" pos = "0.         0.00350000102 0." range="-0.131 0.960"/>
                                    <geom mesh="index_mp" quat = "0.9965159041385382 0.014351051665437375 0.07043887577876032 -0.042290245850220926" pos = "0.02403002404  -0.00167       -0.04701612481"/>
                                    <body name="index_dp_virt" pos="0.   0.  0.0235">
                                        <joint name="index_mp2dp_virt" axis="1 0 0" pos = "0.         0.00370000102 0." range="-0.093 0.682"/>
                                        <inertial pos="0 0 0" mass="0.001" diaginertia="4E-10 4E-10 3E-10" />
                                        <body name="index_dp" pos="0. 0. 0.009">
                                            <joint name="index_mp2dp" axis="1 0 0" pos = "0.         0.00350000102 0." range="-0.093 0.682"/>
                                            <geom mesh="index_dp" quat="0.9965159041385382 0.014351051665437375 0.07043887577876032 -0.042290245850220926" pos = "0.02403002404  -0.00167      -0.07951612481"/>
                                            <body name="index_fingertip" pos="0 0 0.01">
                        
                                            </body>
                                        </body>
                                    </body>
                                </body>
                            </body>
                        </body>
                    </body>
                </body>
            </body>


            <!-- <site name="p21" pos="0.009450 0.082000 -0.003066 " size="0.001" rgba="1 0.1 0.1 1"/> -->
            <!-- <site name="p22" pos="-0.003550 0.082000 0.003434 " size="0.001" rgba="0.1 1 0.1 1"/> -->
            <!-- <site name="p23" pos="-0.003550 0.082000 -0.003066 " size="0.001" rgba="0.1 0.1 0.1 1"/> -->
            <!-- <site name="p24" pos="-0.003550 0.090000 -0.003066 " size="0.001" rgba="0.1 0.1 1 1"/> -->
            <body name="middle_um_virt" quat ="-0.5 0.5 -0.5 -0.5" pos = "0.00295 0.09 -0.003066">
                <joint name="middle_abd_virt" axis = "1 0 0" range="-0.264 0.264"/>
                <inertial pos="0 0 0" mass="0.001" diaginertia="4E-10 4E-10 3E-10" />
                <body name="middle_um" pos="0 0 0.018">
                    <joint name="middle_abd" axis = "1 0 0" range="-0.264 0.264"/>
                    <geom mesh="middle_um" quat=" 0.7071067811865476 -0.0 -0.0 -0.7071067811865475" pos="-0. -0.  0.002"/>
                    <body name="middle_pp_virt" quat="0.7071067811865476 0.0 0.0 -0.7071067811865475" pos="0 0 -0.00743303472">
                        <joint name="root2middle_pp_virt" axis="1 0 0" pos = "0 0.002700001023199999 0" range="-0.157 0.829"/>
                        <inertial pos="0 0 0" mass="0.001" diaginertia="4E-10 4E-10 3E-10" />
                        <body name="middle_pp" pos="0 0 0.018">
                            <joint name="root2middle_pp" axis="1 0 0" pos = "0 0.002500001023199999 0" range="-0.157 0.829"/>
                            <geom mesh="middle_pp" quat="1.0 -0.0 -0.0 -0.0" pos="0.          0.        -0.00858303472"/>
                            <body name="middle_pp_sens" pos="0 -0.004 0.022">
                            </body>
                            <body name="middle_mp_virt" pos="0.          0.         0.03501428277">
                                <joint name="middle_pp2mp_virt" axis="1 0 0"  pos = "0 0.0037000000000999996 0" range="-0.131 0.960"/>
                                <inertial pos="0 0 0" mass="0.001" diaginertia="4E-10 4E-10 3E-10" />
                                <body name="middle_mp" pos=" 0.  0. 0.012">
                                    <joint name="middle_pp2mp" axis="1 0 0" pos = "0 0.0035000000000999996 0" range="-0.131 0.960"/>
                                    <geom mesh="middle_mp" quat="1.0 -0.0 -0.0 -0.0" pos=" 0.           0.        -0.05559731749"/>
                                    <body name="middle_dp_virt" pos="0.   0.  0.0255">
                                        <joint name="middle_mp2dp_virt" axis="1 0 0" pos = "0 0.0037000000000999996 0" range="-0.093 0.682"/>
                                        <inertial pos="0 0 0" mass="0.001" diaginertia="4E-10 4E-10 3E-10" />
                                        <body name="middle_dp" pos="0. 0. 0.009">
                                            <joint name="middle_mp2dp" axis="1 0 0" pos = "0 0.0035000000000999996 0" range="-0.093 0.682"/>
                                            <geom mesh="middle_dp" quat="1.0 -0.0 -0.0 -0.0" pos="0.           0.         -0.09009731749"/>
                                            <body name="middle_fingertip" pos="0 0 0.01">
                                            </body>
                                        </body>
                                    </body>
                                </body>
                            </body>
                        </body>
                    </body>
                </body>
            </body>

            <!-- <site name="p31" pos="-0.009673 0.075194 -0.002943 " size="0.001" rgba="1 0.1 0.1 1"/> -->
            <!-- <site name="p32" pos="-0.021963 0.073609 0.005103 " size="0.001" rgba="0.1 1 0.1 1"/> -->
            <!-- <site name="p33" pos="-0.022497 0.073385 -0.001371 " size="0.001" rgba="0.1 0.1 0.1 1"/> -->
            <!-- <site name="p34" pos="-0.023630 0.081302 -0.001552 " size="0.001" rgba="0.1 0.1 1 1"/> -->
            <body name="ring_um_virt" quat ="0.4301659457827641 -0.5159407823331047 0.503470950251851 0.5433961450606932" pos = "-0.017217999999999997 0.08220650000000002 -0.002338">
                <joint name="ring_abd_virt" axis = "1 0 0" range="-0.264 0.264"/>
                <inertial pos="0 0 0" mass="0.001" diaginertia="4E-10 4E-10 3E-10" />
                <body name="ring_um" pos="0 0 0.018">
                    <joint name="ring_abd" axis = "1 0 0" range="-0.264 0.264"/>
                    <geom mesh="ring_um" quat="0.6747394337578664 0.05995553267210752 0.039660080772529006 -0.7345468729953413" pos="-0.00167054668 -0.02384603398   0.00667182377"/>
                    <body name="ring_pp_virt" quat="0.7071067811865476 -8.673617379884035e-18 3.469446951953614e-18 -0.7071067811865475" pos="0 0 -0.00743303472">
                        <joint name="root2ring_pp_virt" axis="1 0 0" pos = "0 0.002700001023199999 0" range="-0.157 0.829"/>
                        <inertial pos="0 0 0" mass="0.001" diaginertia="4E-10 4E-10 3E-10" />
                        <body name="ring_pp" pos="0 0 0.018">
                            <joint name="root2ring_pp" axis="1 0 0" pos = "0 0.002500001023199999 0" range="-0.157 0.829"/>
                            <geom mesh="ring_pp" quat="0.9965159041385382 0.014351051665437375 0.07043887577876032 -0.042290245850220926" pos="0.02384603398 -0.00167054668  -0.00391121095"/>
                            <body name="ring_pp_sens" pos="0 -0.004 0.018">
                            </body>
                            <body name="ring_mp_virt" pos="0.          0.         0.03101612481">
                                <joint name="ring_pp2mp_virt" axis="1 0 0" pos = "0 0.0037000000000999996 0" range="-0.131 0.960"/>
                                <inertial pos="0 0 0" mass="0.001" diaginertia="4E-10 4E-10 3E-10" />
                                <body name="ring_mp" pos=" 0.  0. 0.012">
                                    <joint name="ring_pp2mp" axis="1 0 0" pos="0 0.0035000000000999996 0" range="-0.131 0.960"/>
                                    <geom mesh="ring_mp" quat="0.9965159041385382 0.014351051665437375 0.07043887577876032 -0.042290245850220926" pos="0.02384603398  -0.00167054668 -0.04692733575"/> 
                                    <body name="ring_dp_virt" pos="0.   0.  0.0235">
                                        <joint name="ring_mp2dp_virt" axis="1 0 0" pos = "0 0.0037000000000999996 0" range="-0.093 0.682"/>
                                        <inertial pos="0 0 0" mass="0.001" diaginertia="4E-10 4E-10 3E-10" />
                                        <body name="ring_dp" pos="0. 0. 0.009">
                                            <joint name="ring_mp2dp" axis="1 0 0" pos = "0 0.0035000000000999996 0" range="-0.093 0.682"/>
                                            <geom mesh="ring_dp" quat="0.9965159041385382 0.014351051665437375 0.07043887577876032 -0.042290245850220926" pos="0.02384603398  -0.00167054668 -0.07942733575"/>
                                            <body name="ring_fingertip" pos="0 0 0.01">
                                            </body>
                                        </body>
                                    </body>
                                </body>
                            </body>
                        </body>
                    </body>
                </body>
            </body>

            <!-- <site name="p41" pos="-0.027327 0.067948 0.003204 " size="0.001" rgba="1 0.1 0.1 1"/> -->
            <!-- <site name="p42" pos="-0.038636 0.063821 0.011348 " size="0.001" rgba="0.1 1 0.1 1"/> -->
            <!-- <site name="p43" pos="-0.039424 0.063502 0.004904 " size="0.001" rgba="0.1 0.1 0.1 1"/> -->
            <!-- <site name="p44" pos="-0.042188 0.071009 0.004870 " size="0.001" rgba="0.1 0.1 1 1"/> -->
            <body name="pinky_um_virt" quat ="0.36487773736255025 -0.5534044763378659 0.44257442579699546 0.6039334400220425" pos = "-0.036139500000000005 0.073232 0.004020000000000001">
                <joint name="pinky_abd_virt" axis = "1 0 0" range="-0.264 0.264"/>
                <inertial pos="0 0 0" mass="0.001" diaginertia="4E-10 4E-10 3E-10" />
                <body name="pinky_um" pos="0 0 0.018">
                    <joint name="pinky_abd" axis = "1 0 0" range="-0.264 0.264"/>
                    <geom mesh="pinky_um" quat="0.6493012108840017 0.13334027183711064 0.11409631699812431 -0.7400069863848843" pos="0.00047677564 -0.04987701158   0.00302781341"/>
                    <body name="pinky_pp_virt" quat="0.7071067811865477 0 0 -0.7071067811865476" pos="0 0 -0.00743303472">
                        <joint name="root2pinky_pp_virt" axis="1 0 0" pos = "0.         0.00270000102 0." range="-0.157 0.829"/>
                        <inertial pos="0 0 0" mass="0.001" diaginertia="4E-10 4E-10 3E-10" />
                        <body name="pinky_pp" pos="0 0 0.018">
                            <joint name="root2pinky_pp" axis="1 0 0" pos = "0.         0.00250000102 0." range="-0.157 0.829"/>
                            <geom mesh="pinky_pp" quat="0.9823892474468868 0.01360753096349492 0.17496408987906217 -0.06413866894945879" pos="0.04987701158  0.00047677564 -0.00755522131"/>
                            <body name="pinky_pp_sens" pos="0 -0.004 0.015">
                            </body>
                            <body name="pinky_mp_virt" pos="0 0 0.02701851213434598">
                                <joint name="pinky_pp2mp_virt" axis="1 0 0" pos = "0.         0.00370000102 0." range="-0.131 0.960"/>
                                <inertial pos="0 0 0" mass="0.001" diaginertia="4E-10 4E-10 3E-10" />
                                <body name="pinky_mp" pos="0 0 0.011999999999999998">
                                    <joint name="pinky_pp2mp" axis="1 0 0" pos = "0.         0.00350000102 0." range="-0.131 0.960"/>
                                    <geom mesh="pinky_mp" quat="0.9823892474468868 0.01360753096349492 0.17496408987906217 -0.06413866894945879" pos="0.04987701158   0.00047677564 -0.04657373345"/> <!--pos pp + shift from mpvirt and mp-->
                                    <body name="pinky_dp_virt" pos="0 0 0.0195">
                                        <joint name="pinky_mp2dp_virt" axis="1 0 0" pos = "0.         0.00370000102 0." range="-0.093 0.682"/>
                                        <inertial pos="0 0 0" mass="0.001" diaginertia="4E-10 4E-10 3E-10" />
                                        <body name="pinky_dp" pos="0 0 0.008999999999999998">
                                            <joint name="pinky_mp2dp" axis="1 0 0" pos = "0.         0.00350000102 0." range="-0.093 0.682"/>
                                            <geom mesh="pinky_dp" quat="0.9823892474468868 0.01360753096349492 0.17496408987906217 -0.06413866894945879" pos="0.04987701158   0.00047677564  -0.07507373345"/>
                                            <body name="pinky_fingertip" pos="0 0 0.01" >
                                            </body>
                                        </body>
                                    </body>
                                </body>
                            </body>
                        </body>
                    </body>
                </body>
            </body>
        </body>
    </body>

</mujoco>